Workbook
Name Men_Group_A_Result_Table: Rankings!$B$3:$F$6
Name Men_Group_B_Result_Table: Rankings!$B$10:$F$13
Name Men_Group_B_Result_Table: #REF!
Name MenFieldPlayers: _xlfn.ANCHORARRAY('MVP Voting'!$V$2)
Name MenGoalkeepers: _xlfn.ANCHORARRAY('MVP Voting'!$X$2)
Name Women_Result_Table: Rankings!$B$17:$F$21
Name Women_Result_Table: #REF!
Name WomenFieldPlayers: _xlfn.ANCHORARRAY('MVP Voting'!$W$2)
Name WomenGoalkeepers: _xlfn.ANCHORARRAY('MVP Voting'!$Y$2)

Sheet ----- NAVIGATION -----
A1: 🧭 BAY CLASSIC 2027: WORKBOOK NAVIGATION
A2: Click any sheet name below to jump straight there. New to this workbook? Start with the Admin Manual.
A4: START HERE
B5: Control Panel | C5: Live dashboard: registration, finance, games, current leaders. Open this first every time.
B6: Admin Manual | C6: Full step-by-step guide for running the tournament in this workbook.
B7: Volunteer Guide | C7: Quick guide for volunteers (non-organizers).
B8: Model Notes | C8: Running log of cleanup/action items for the model itself (organizer use only).
A10: MASTER DATA
B11: Inputs | C11: All tournament settings: dates, times, fee, capacity, venue. Change things here first.
B12: Format Engine | C12: Internal engine that builds the schedule shape from your format choice. Don't edit.
B13: Standings Engine | C13: Internal ranking calculations. Don't edit: see Rankings for the readable output.
B14: Teams Master | C14: Master list of all teams, divisions, group codes, jerseys, contacts.
B15: Referees Master | C15: Referee roster and pairings.
B16: Medical Staff Master | C16: Medical staff (physio / athletic trainer) roster, hours and pay.
B17: Products Master | C17: Concession product list: cost, price, margin.
A19: REGISTRATION
B20: Registration 2027 | C20: Team invitations, deposits, payments, roster status & capacity settings
A22: GAME OPERATIONS
B23: Games Schedule | C23: The schedule engine: matchups, times, scores, referees, volunteers.
B24: Group Draw | C24: Randomized group draw tool; locks codes into Teams Master.
B25: Printable Schedule | C25: Clean printable version of the schedule.
B26: Rankings | C26: Group standings, calculated automatically from scores.
B27: Final Rankings | C27: Final tournament placings and awards.
A29: TEAM ROSTERS
B30: Rosters Master | C30: All team rosters in one place.
B31: Roster Template | C31: Blank template teams use to submit rosters.
A33: STATISTICS & MVP
B34: Stats & MVP | C34: Top scorers and MVP/MVG leaders, calculated automatically.
B35: Individuals Stats Men | C35: Enter men's goals per game per player.
B36: Individuals Stats Women | C36: Enter women's goals per game per player.
B37: Voters Master | C37: List of eligible MVP voters.
B38: Officials Contacts | C38: Contact info for team officials.
B39: MVP Voting | C39: Enter MVP / MVG votes.
A41: VOLUNTEERS
B42: Volunteer Master List | C42: Master volunteer list; hours auto-tally from the assignment sheets.
B43: Gym Prep | C43: Gym setup/teardown volunteer assignments.
B44: Referee Pickup Drop Off | C44: Referee transportation volunteer assignments.
A46: FINANCE
B47: Budget Dashboard | C47: Multi-year P&L: income, expenses, net profit, variance.
B48: Multi Year Financial Summary | C48: Detailed year-by-year actuals (source of truth for Budget Dashboard).
...

Sheet Control Panel
B2: 🏆 BAY CLASSIC 2027: CONTROL PANEL | F2: TOURNAMENT FORMAT | G2: 8M+4W | H2: 📖 New here? Open the Admin Manual
B3: ="Tournament starts "&TEXT(Inputs!C22,"dddd, mmm d, yyyy")&" • "&Inputs!C23 | F3: Configuration | G3: =Inputs!C13&" teams ("&Inputs!C14&"M / "&Inputs!C15&"W)" | H3: 🧭 See full workbook map
B4: Everything on this page calculates automatically: nothing to type here. Change settings on Inputs; log scores on Games Schedule.
B5: REGISTRATION | F5: CURRENT LEADERS
B6: Teams Registered | C6: =COUNTIF('Registration 2027'!$J$2:$J$40,"Fully Registered")+COUNTIF('Registration 2027'!$J$2:$J$40,"Host Registered") | D6: ="of "&Inputs!C13&" max" | F6: Top Scorer (M) | G6: ='Stats & MVP'!B6&": "&'Stats & MVP'!D6&" goals"
B7: Fees Collected | C7: =SUM('Registration 2027'!$H$2:$H$40) | D7: ="of "&TEXT(Inputs!C18*(Inputs!C13-'Registration 2027'!$R$9),"$#,##0")&" expected" | F7: Top Scorer (W) | G7: ='Stats & MVP'!B15&": "&'Stats & MVP'!D15&" goals"
F8: MVP (M) | G8: ='Stats & MVP'!G8
B9: FINANCE (2027 Budget) | F9: MVP (W) | G9: ='Stats & MVP'!G9
B10: Total Income | C10: ='Budget Dashboard'!A5
B11: Total Expenses | C11: ='Budget Dashboard'!B5 | F11: GROUP LEADERS
B12: Net Profit | C12: ='Budget Dashboard'!C5 | F12: Group A | G12: =Rankings!B3
F13: Group B | G13: =Rankings!B10
B14: GAMES | F14: Women | G14: =Rankings!B17
B15: Total Games | C15: =COUNT('Games Schedule'!$C$5:$C$31)
B16: Games Played | C16: {=SUMPRODUCT((('Games Schedule'!$S$5:$S$31+'Games Schedule'!$T$5:$T$31)>0)*1)}
B17: Goals Scored | C17: =SUM('Games Schedule'!$S$5:$T$31)
B19: PAYMENT TRACKER
B20: Status | C20: Teams
B21: Fully Registered | C21: =COUNTIF('Registration 2027'!$J$2:$J$40,"Fully Registered")
B22: Host Registered | C22: =COUNTIF('Registration 2027'!$J$2:$J$40,"Host Registered")
B23: Deposit Paid only | C23: =COUNTIF('Registration 2027'!$J$2:$J$40,"Deposit Paid")
B24: Not Registered | C24: =COUNTIF('Registration 2027'!$A$2:$A$40,"?*")-C21-C22-C23

Sheet Model Notes
A1: Bay Classic 2027: Model Notes & Action Items
A2: Open items to revisit, clean up, automate, or link. Example rows show how to use the log; replace them with your own.
A4: # | B4: Item | C4: Category | D4: Location | E4: Suggested action / status
A5: 1 | B5: Assign referee pairs to playoff games | C5: Revisit | D5: Games Schedule P23:P28 | E5: OPEN: pick a pair from the box at P34 once group standings are final. Q40 should read 0 and the conflict check at P43 should stay clear.
A6: 2 | B6: Confirm medical staff hours | C6: Revisit | D6: Medical Staff Master / Games Schedule AA | E6: OPEN: make sure every game has a name in col AA. Hours and pay update automatically on Medical Staff Master.
A7: 3 | B7: Reconcile final payments | C7: Clean up | D7: Registration 2027 cols E:H | E7: IN PROGRESS: enter the Final Pay Date as each balance arrives. Status and Fees Collected update by themselves.
A8: 4 | B8: Collect missing rosters | C8: Revisit | D8: Registration 2027 col I / Rosters Master | E8: OPEN: chase any team without an "x" in Roster Submitted before the draw, then paste the roster into its block.
A9: 5 | B9: Lock the group draw | C9: Link | D9: Group Draw I6:I18 to Teams Master E | E9: DONE: codes pasted as values into Teams Master col E, so the schedule no longer changes on recalculation.
A10: 6 | B10: Update concession prices | C10: Clean up | D10: Products Master | E10: DONE: COGS and sale prices reviewed. Price List Concession picks them up automatically.
A11: 7 | B11: Book referee travel | C11: Revisit | D11: Referees Master / Referee Pickup Drop Off | E11: OPEN: type flight and hotel costs as they are booked, and add airport pickup times and drivers.
A12: 8 | B12: Review budget vs actuals after the event | C12: Revisit | D12: Budget Dashboard col I | E12: OPEN: type 2027 actuals as money comes in or goes out, then compare with the 2027 Budget column.
A17: Completed this review (for reference)
A18: ✓ Group codes locked into Teams Master after the public draw.
A19: ✓ Referee pair labels checked against Referees Master col T.
A20: ✓ Volunteer and medical staff names match the dropdown lists on Games Schedule.
A21: ✓ Inputs reviewed: start date, fee, deposit %, venue and daily start times.

Sheet Admin Manual
A1: BAY CLASSIC 2027: ORGANIZER ADMIN MANUAL
A2: Master operating guide for the tournament workbook. Read the Executive Summary first, then jump to the function you need.
A4: 1. EXECUTIVE SUMMARY
A5: What this workbook does | B5: Runs the entire tournament from one file: registration & payments, the group draw, the game schedule, scores & rankings, player stats & MVP voting, volunteer assignments, concessions, and the full multi-year budget.
A6: The big idea | B6: It is DRIVER-BASED. You type a small number of inputs in a few designated places; everything else is formulas that recalculate automatically. You almost never edit calculated cells.
A7: The 3 places you actually type | B7: 1) INPUTS sheet: all tournament settings (dates, times, fee, capacity, venue). 2) The MASTER DATA tables: Teams, Referees, Rosters, Products, Medical Staff. 3) A few clearly marked entry cells: game scores, player goals, MVP votes, volunteer names.
A8: Where to look at a glance | B8: CONTROL PANEL: live dashboard of registration, finance, games and current leaders. Open this first every time to see tournament status at a glance.
A9: Golden rule | B9: If a cell already contains a formula (it calculates a result), DO NOT overwrite it. Only edit input cells. The font color tells you which is which; see Section 5.
A11: 2. HOW THE MODEL WORKS (data flow)
A12: Read this top-to-bottom: each layer feeds the next. Change something upstream and everything downstream follows.
A13: Layer | B13: Sheets | C13: Feeds into →
A14: 1. INPUTS (settings) | B14: Inputs | C14: Games Schedule (dates/times), Registration & Budget (fee/capacity), Game Sheet (venue), Control Panel.
A15: 2. MASTER DATA | B15: Teams Master, Referees Master, Rosters Master, Products Master, Medical Staff Master | C15: Group Draw & Games Schedule (team names), Game Sheet (rosters/refs), Concession (products), Budget (medical staff).
A16: 3. REGISTRATION | B16: Registration 2027 | C16: Control Panel (teams registered, fees collected), Budget Dashboard (paying-team count drives 2027 income).
A17: 4. DRAW | B17: Group Draw | C17: Writes Group Codes into Teams Master → which feed Games Schedule team matchups.
A18: 5. GAME OPERATIONS | B18: Games Schedule (engine), Printable Schedule, Game Sheet | C18: Rankings (from scores), Stats, Control Panel. Game Sheet pulls from Schedule + Rosters.
A19: 6. RESULTS | B19: Rankings, Final Rankings, Stats & MVP, Individuals Stats, MVP Voting | C19: Control Panel leaders, Final Rankings awards, jersey-color logic in Games Schedule.
A20: 7. VOLUNTEERS | B20: Volunteer Master List, Gym Prep, Referee Pickup Drop Off (Merch Booth assignment is a column on Games Schedule, not a separate sheet) | C20: Hours auto-tally on the Volunteer Master List from the assignment sheets.
A21: 8. FINANCE | B21: Budget Dashboard, Multi Year Financial Summary, Operations Costs, Concession sheets, Price List | C21: Control Panel finance KPIs. Concession detail rolls up into the Budget Dashboard.
A23: 3. WHERE TO START (setup order for a new year)
A24: Do these in order. Each step assumes the one above is done.
A25: Step | B25: Do this | C25: On this sheet
A26: 1 | B26: Set tournament settings: start date, venue, fee, capacity, daily start times, game durations. | C26: Inputs (blue cells C6:C29)
A27: 2 | B27: Confirm / update the team list, referees, and medical staff (physio / athletic trainer) for the year. Give every team a Short Name & jersey colors in the Team Styles table (Teams Master, cols O:R). | C27: Teams Master, Referees Master, Medical Staff Master
A28: 3 | B28: Track invitations, deposits and final payments as teams confirm. | C28: Registration 2027
A29: 4 | B29: Run the group draw and lock the Group Codes into Teams Master. | C29: Group Draw → Teams Master
A30: 5 | B30: Verify the auto-built schedule (matchups, times, referee pairs) reads correctly. | C30: Games Schedule
A31: 6 | B31: Load rosters, assign volunteers, set up concession products & pricing. | C31: Rosters Master, volunteer sheets, Products/Price List
A32: 7 | B32: During the event: enter scores, goals, votes, and mark volunteer presence. | C32: Games Schedule, Individuals Stats, MVP Voting
A33: 8 | B33: After: confirm final rankings & awards, reconcile actuals in the budget. | C33: Final Rankings, Budget Dashboard
A35: 4. FUNCTION RECIPES
A36: Each block: a one-line summary, where the drivers are, then click-by-click steps.
A38: ▶ 4.1 SET TOURNAMENT SETTINGS
A39: Summary | B39: All global settings live on the Inputs sheet. Change them here and dates, times, fees and capacity update everywhere automatically.
A40: Drivers | B40: Inputs sheet, blue cells: game minutes C6:C9 · capacity C13:C14 · fee C18 · deposit % C19 · start date C22 · venue C23 · daily start times C26:C29.
A41: Steps | B41: 1. Open Inputs. 2. Edit only the yellow/blue cells in column C. 3. Set Tournament Start Date (C22): Day 1; all game dates flow from this. 4. Set the first court time for each day (C26:C29). 5. Done: Games Schedule, Control Panel and Budget recalculate automatically.
A43: ▶ 4.2 BUILD / VERIFY THE SCHEDULE
A44: Summary | B44: The Games Schedule is the engine. Game numbers, dates and all the clock times (court, game, halftime, second half, end) are calculated. Matchups come from Group Codes; team names, jersey colors and referee pairs auto-resolve.
A45: Drivers | B45: Times ← Inputs. Matchups ← 'Code Team A' col L & 'Code Team B' col M (you set these codes). Names ← Teams Master. Jerseys ← Rankings. Referees typed in col P.
A46: Steps | B46: 1. Set times via Inputs (recipe 4.1): do NOT type clock times directly here. 2. In cols L & M, enter each game's Group Codes (e.g. A1 vs A2). Team names in N & O fill automatically. 3. Assign a referee pair per game in col P (pairs are listed in the box at P34:P38). 4. Check the 'TBD' cells: they mean a code has no matching team yet. 5. Never insert or delete rows; formulas depend on row positions.
...

Sheet Volunteer Guide
A1: VOLUNTEER QUICK REFERENCE GUIDE
A3: ⚠️ IMPORTANT: Make sure you are NOT playing when you volunteer!
A5: YOUR VOLUNTEER ROLES
A7: 🕐 TIME KEEPER
A8: Location: Scorer's table
A9: Duties:
A10: • Start/stop game clock
A11: ="• Sound horn at halftime ("&Inputs!C7/2&" min) and end of game ("&Inputs!C7&" min)"
A12: • Track timeouts (1 per team per half, 1 minute each)
A13: • Signal 2-minute suspensions
A14: Arrive: 10 minutes before Court Time
A16: 📋 SCORE KEEPER
A17: Location: Scorer's table
A18: Duties:
A19: • Record all goals on score sheet
A20: • Track player suspensions (2 min, red cards)
A21: • Track timeouts used
A22: • Verify final score with referees
A23: Arrive: 10 minutes before Court Time
A25: 🏪 MERCHANDISE BOOTH
... A47: GAME TIMING
A49: Time | B49: Event
A50: Court Time | B50: ="Teams begin warm-up ("&Inputs!C6&" min)"
A51: Game Time | B51: ="First half starts ("&Inputs!C7/2&" min)"
A52: Halftime | B52: ="Break ("&Inputs!C8&" min)"
A53: Second Half | B53: ="Resumes ("&Inputs!C7/2&" min)"
A54: End of Game | B54: ="Maximum ~"&Inputs!C10&" min after Court Time"
A56: CHECK-IN PROCESS
A57: 1. Arrive 10 minutes before your assigned time
A58: 2. Find tournament coordinator or check-in desk
A59: 3. Your attendance will be marked in "Presence Verified" column
A60: 4. Get brief instructions from coordinator if needed
A62: QUESTIONS?
A63: Find any board member (marked in Participants list)
A64: They can help with any issues during your shift
A66: THANK YOU FOR VOLUNTEERING! 🙌

Sheet ----- MASTER DATA -----
A1: MASTER DATA

Sheet Inputs
B2: TOURNAMENT INPUTS & ASSUMPTIONS | C2: TOURNAMENT INPUTS & ASSUMPTIONS
B3: Central source for all tournament settings. Edit here: the rest of the model reads from these cells.
B5: GAME PARAMETERS (minutes)
B6: Warm up | C6: 5
B7: Actual play | C7: 50
B8: Halftime | C8: 5
B9: Incidents/buffer | C9: 5
B10: Total slot | C10: =SUM(C6:C9)
B12: TOURNAMENT CAPACITY
B13: Max Total Teams | C13: ='Format Engine'!H8
B14: Max Men's Teams | C14: ='Format Engine'!H9
B15: Max Women's Teams | C15: ='Format Engine'!H10
B17: REGISTRATION FEE
B18: Per-Team Fee | C18: 600
B19: Deposit % of Fee | C19: 0.35
B21: EVENT DETAILS
B22: Tournament Start Date | C22: 46430
B23: Venue Name / Location | C23: Northside Community Gym, Springfield, CA
B25: DAILY START TIMES (first court time each day)
B26: Day 1 Start (Game 1) | C26: 0.60416667
B27: Day 2 Start (Game 2) | C27: 0.33333333
B28: Day 3 Start (Game 8) | C28: 0.35416667
B29: Day 4 Start (Game 21) | C29: 0.35416667

Sheet Format Engine
B1: FORMAT ENGINE: Tournament Format Toggle
B2: Single switch that re-shapes the whole tournament. Change the Active Format on the Control Panel; every tab follows.
B3: The grid below (rows 22-91) is the static master game plan for each format: only edit it to redesign a format. The ACTIVE block (H7:H22) and active schedule update automatically from the toggle.
B4: ACTIVE FORMAT → | C4: ='Control Panel'!$G$2 | D4: (driven by Control Panel toggle G2)
B6: PARAMETERS BY FORMAT | C6: Format 1 | D6: Format 2 | E6: Format 3 | G6: ACTIVE | H6: ↓ read by all tabs
B7: Format name | C7: 8M+5W | D7: 8M+4W | E7: 6M+6W | G7: Active format | H7: =$C$4
B8: Total teams | C8: 13 | D8: 12 | E8: 12 | G8: Total teams | H8: =INDEX($C$8:$E$8,MATCH($C$4,$C$7:$E$7,0))
B9: Men teams | C9: 8 | D9: 8 | E9: 6 | G9: Men teams | H9: =INDEX($C$9:$E$9,MATCH($C$4,$C$7:$E$7,0))
B10: Women teams | C10: 5 | D10: 4 | E10: 6 | G10: Women teams | H10: =INDEX($C$10:$E$10,MATCH($C$4,$C$7:$E$7,0))
B11: Men groups | C11: 2 | D11: 2 | E11: 2 | G11: Men groups | H11: =INDEX($C$11:$E$11,MATCH($C$4,$C$7:$E$7,0))
B12: Women groups | C12: 1 | D12: 1 | E12: 2 | G12: Women groups | H12: =INDEX($C$12:$E$12,MATCH($C$4,$C$7:$E$7,0))
B13: Total games | C13: =COUNTIF($A$23:$A$200,C$7) | D13: =COUNTIF($A$23:$A$200,D$7) | E13: =COUNTIF($A$23:$A$200,E$7) | G13: Total games | H13: =INDEX($C$13:$E$13,MATCH($C$4,$C$7:$E$7,0))
B14: Day 1 games | C14: 1 | D14: 7 | E14: 6 | G14: Day 1 games | H14: =INDEX($C$14:$E$14,MATCH($C$4,$C$7:$E$7,0))
B15: Day 2 games | C15: 6 | D15: 11 | E15: 8 | G15: Day 2 games | H15: =INDEX($C$15:$E$15,MATCH($C$4,$C$7:$E$7,0))
B16: Day 3 games | C16: 13 | D16: 6 | E16: 4 | G16: Day 3 games | H16: =INDEX($C$16:$E$16,MATCH($C$4,$C$7:$E$7,0))
B17: Day 4 games | C17: 7 | D17: 0 | E17: 0 | G17: Day 4 games | H17: =INDEX($C$17:$E$17,MATCH($C$4,$C$7:$E$7,0))
F18: Day-1 last game # | H18: =H14
F19: Day-2 last game # | H19: =H14+H15
F20: Day-3 last game # | H20: =H14+H15+H16
F21: Day-4 last game # | H21: =H13 | J21: ACTIVE SCHEDULE (auto-filters to selected format)
A22: FormatKey | B22: Game | C22: Div | D22: Gr | E22: CodeA | F22: Active tournament days | G22: K | H22: =COUNTIF(H14:H17,">0") | J22: Game | K22: Div | L22: Gr | M22: CodeA | N22: CodeB | O22: K
A23: 8M+5W | B23: 1 | C23: W | D23: W | E23: W1 | F23: W2 | J23: {=_xlfn._xlws.FILTER(B23:G91,A23:A91=$C$4)}
A24: 8M+5W | B24: 2 | C24: M | D24: A | E24: A1 | F24: A2
A25: 8M+5W | B25: 3 | C25: M | D25: B | E25: B1 | F25: B2
A26: 8M+5W | B26: 4 | C26: W | D26: W | E26: W3 | F26: W4
A27: 8M+5W | B27: 5 | C27: M | D27: A | E27: A3 | F27: A4
A28: 8M+5W | B28: 6 | C28: M | D28: B | E28: B3 | F28: B4
A29: 8M+5W | B29: 7 | C29: W | D29: W | E29: W1 | F29: W5
A30: 8M+5W | B30: 8 | C30: M | D30: A | E30: A1 | F30: A3
A31: 8M+5W | B31: 9 | C31: W | D31: W | E31: W2 | F31: W5
A32: 8M+5W | B32: 10 | C32: M | D32: B | E32: B1 | F32: B3
A33: 8M+5W | B33: 11 | C33: W | D33: W | E33: W1 | F33: W4
A34: 8M+5W | B34: 12 | C34: M | D34: A | E34: A2 | F34: A4
A35: 8M+5W | B35: 13 | C35: W | D35: W | E35: W3 | F35: W5
... A44: 8M+5W | B44: 22 | C44: W | D44: W | E44: W4 | F44: W5
A45: 8M+5W | B45: 23 | C45: M | D45: P | E45: A4 | F45: B4 | G45: 7
A46: 8M+5W | B46: 24 | C46: M | D46: P | E46: A3 | F46: B3 | G46: 5
A47: 8M+5W | B47: 25 | C47: M | D47: P | E47: A2 | F47: B2 | G47: 3
A48: 8M+5W | B48: 26 | C48: W | D48: P | E48: W1 | F48: W2 | G48: 1
A49: 8M+5W | B49: 27 | C49: M | D49: P | E49: A1 | F49: B1 | G49: 1
...

Sheet Standings Engine
B1: STANDINGS ENGINE: code-driven group standings (all formats)
B2: Group = code prefix, seed = digit. Points from non-playoff games only. Playoff matchups resolve their codes (e.g. A1 = Group A winner) against the RankedCode column.
A3: Team | B3: Code | C3: Group | D3: Pts | E3: GF | F3: GA | G3: GD | H3: RankScore | I3: RankInGrp | J3: RankedCode | K3: Active?
A4: ='Teams Master'!C2 | B4: ='Teams Master'!E2 | C4: =IF(B4="","",LEFT(B4,LEN(B4)-1)) | D4: =SUMIFS('Games Schedule'!$U$5:$U$31,'Games Schedule'!$L$5:$L$31,$B4,'Games Schedule'!$J$5:$J$31,"<>P")+SUMIFS('Games Schedule'!$V$5:$V$31,'Games Schedule'!$M$5:$M$31,$B4,'Games Schedule'!$J$5:$J$31,"<>P") | E4: =SUMIFS('Games Schedule'!$S$5:$S$31,'Games Schedule'!$L$5:$L$31,$B4,'Games Schedule'!$J$5:$J$31,"<>P")+SUMIFS('Games Schedule'!$T$5:$T$31,'Games Schedule'!$M$5:$M$31,$B4,'Games Schedule'!$J$5:$J$31,"<>P") | F4: =SUMIFS('Games Schedule'!$T$5:$T$31,'Games Schedule'!$L$5:$L$31,$B4,'Games Schedule'!$J$5:$J$31,"<>P")+SUMIFS('Games Schedule'!$S$5:$S$31,'Games Schedule'!$M$5:$M$31,$B4,'Games Schedule'!$J$5:$J$31,"<>P") | G4: =E4-F4 | H4: =D4*1000+G4 | I4: {=IF($C4="","",IF($K4=0,"",SUMPRODUCT(($C$4:$C$16=$C4)*($K$4:$K$16=1)*($H$4:$H$16>$H4))+SUMPRODUCT(($C$4:$C$16=$C4)*($K$4:$K$16=1)*($H$4:$H$16=$H4)*(ROW($H$4:$H$16)<ROW($H4)))+1))} | J4: =IF($C4="","",IF($K4=0,"",$C4&I4)) | K4: =IF($B4="","",IF((COUNTIFS('Format Engine'!$A$23:$A$91,'Format Engine'!$C$4,'Format Engine'!$E$23:$E$91,$B4,'Format Engine'!$D$23:$D$91,"<>P")+COUNTIFS('Format Engine'!$A$23:$A$91,'Format Engine'!$C$4,'Format Engine'!$F$23:$F$91,$B4,'Format Engine'!$D$23:$D$91,"<>P"))>0,1,0))
A5: ='Teams Master'!C3 | B5: ='Teams Master'!E3 | C5: =IF(B5="","",LEFT(B5,LEN(B5)-1)) | D5: =SUMIFS('Games Schedule'!$U$5:$U$31,'Games Schedule'!$L$5:$L$31,$B5,'Games Schedule'!$J$5:$J$31,"<>P")+SUMIFS('Games Schedule'!$V$5:$V$31,'Games Schedule'!$M$5:$M$31,$B5,'Games Schedule'!$J$5:$J$31,"<>P") | E5: =SUMIFS('Games Schedule'!$S$5:$S$31,'Games Schedule'!$L$5:$L$31,$B5,'Games Schedule'!$J$5:$J$31,"<>P")+SUMIFS('Games Schedule'!$T$5:$T$31,'Games Schedule'!$M$5:$M$31,$B5,'Games Schedule'!$J$5:$J$31,"<>P") | F5: =SUMIFS('Games Schedule'!$T$5:$T$31,'Games Schedule'!$L$5:$L$31,$B5,'Games Schedule'!$J$5:$J$31,"<>P")+SUMIFS('Games Schedule'!$S$5:$S$31,'Games Schedule'!$M$5:$M$31,$B5,'Games Schedule'!$J$5:$J$31,"<>P") | G5: =E5-F5 | H5: =D5*1000+G5 | I5: {=IF($C5="","",IF($K5=0,"",SUMPRODUCT(($C$4:$C$16=$C5)*($K$4:$K$16=1)*($H$4:$H$16>$H5))+SUMPRODUCT(($C$4:$C$16=$C5)*($K$4:$K$16=1)*($H$4:$H$16=$H5)*(ROW($H$4:$H$16)<ROW($H5)))+1))} | J5: =IF($C5="","",IF($K5=0,"",$C5&I5)) | K5: =IF($B5="","",IF((COUNTIFS('Format Engine'!$A$23:$A$91,'Format Engine'!$C$4,'Format Engine'!$E$23:$E$91,$B5,'Format Engine'!$D$23:$D$91,"<>P")+COUNTIFS('Format Engine'!$A$23:$A$91,'Format Engine'!$C$4,'Format Engine'!$F$23:$F$91,$B5,'Format Engine'!$D$23:$D$91,"<>P"))>0,1,0))
A6: ='Teams Master'!C4 | B6: ='Teams Master'!E4 | C6: =IF(B6="","",LEFT(B6,LEN(B6)-1)) | D6: =SUMIFS('Games Schedule'!$U$5:$U$31,'Games Schedule'!$L$5:$L$31,$B6,'Games Schedule'!$J$5:$J$31,"<>P")+SUMIFS('Games Schedule'!$V$5:$V$31,'Games Schedule'!$M$5:$M$31,$B6,'Games Schedule'!$J$5:$J$31,"<>P") | E6: =SUMIFS('Games Schedule'!$S$5:$S$31,'Games Schedule'!$L$5:$L$31,$B6,'Games Schedule'!$J$5:$J$31,"<>P")+SUMIFS('Games Schedule'!$T$5:$T$31,'Games Schedule'!$M$5:$M$31,$B6,'Games Schedule'!$J$5:$J$31,"<>P") | F6: =SUMIFS('Games Schedule'!$T$5:$T$31,'Games Schedule'!$L$5:$L$31,$B6,'Games Schedule'!$J$5:$J$31,"<>P")+SUMIFS('Games Schedule'!$S$5:$S$31,'Games Schedule'!$M$5:$M$31,$B6,'Games Schedule'!$J$5:$J$31,"<>P") | G6: =E6-F6 | H6: =D6*1000+G6 | I6: {=IF($C6="","",IF($K6=0,"",SUMPRODUCT(($C$4:$C$16=$C6)*($K$4:$K$16=1)*($H$4:$H$16>$H6))+SUMPRODUCT(($C$4:$C$16=$C6)*($K$4:$K$16=1)*($H$4:$H$16=$H6)*(ROW($H$4:$H$16)<ROW($H6)))+1))} | J6: =IF($C6="","",IF($K6=0,"",$C6&I6)) | K6: =IF($B6="","",IF((COUNTIFS('Format Engine'!$A$23:$A$91,'Format Engine'!$C$4,'Format Engine'!$E$23:$E$91,$B6,'Format Engine'!$D$23:$D$91,"<>P")+COUNTIFS('Format Engine'!$A$23:$A$91,'Format Engine'!$C$4,'Format Engine'!$F$23:$F$91,$B6,'Format Engine'!$D$23:$D$91,"<>P"))>0,1,0))
A7: ='Teams Master'!C5 | B7: ='Teams Master'!E5 | C7: =IF(B7="","",LEFT(B7,LEN(B7)-1)) | D7: =SUMIFS('Games Schedule'!$U$5:$U$31,'Games Schedule'!$L$5:$L$31,$B7,'Games Schedule'!$J$5:$J$31,"<>P")+SUMIFS('Games Schedule'!$V$5:$V$31,'Games Schedule'!$M$5:$M$31,$B7,'Games Schedule'!$J$5:$J$31,"<>P") | E7: =SUMIFS('Games Schedule'!$S$5:$S$31,'Games Schedule'!$L$5:$L$31,$B7,'Games Schedule'!$J$5:$J$31,"<>P")+SUMIFS('Games Schedule'!$T$5:$T$31,'Games Schedule'!$M$5:$M$31,$B7,'Games Schedule'!$J$5:$J$31,"<>P") | F7: =SUMIFS('Games Schedule'!$T$5:$T$31,'Games Schedule'!$L$5:$L$31,$B7,'Games Schedule'!$J$5:$J$31,"<>P")+SUMIFS('Games Schedule'!$S$5:$S$31,'Games Schedule'!$M$5:$M$31,$B7,'Games Schedule'!$J$5:$J$31,"<>P") | G7: =E7-F7 | H7: =D7*1000+G7 | I7: {=IF($C7="","",IF($K7=0,"",SUMPRODUCT(($C$4:$C$16=$C7)*($K$4:$K$16=1)*($H$4:$H$16>$H7))+SUMPRODUCT(($C$4:$C$16=$C7)*($K$4:$K$16=1)*($H$4:$H$16=$H7)*(ROW($H$4:$H$16)<ROW($H7)))+1))} | J7: =IF($C7="","",IF($K7=0,"",$C7&I7)) | K7: =IF($B7="","",IF((COUNTIFS('Format Engine'!$A$23:$A$91,'Format Engine'!$C$4,'Format Engine'!$E$23:$E$91,$B7,'Format Engine'!$D$23:$D$91,"<>P")+COUNTIFS('Format Engine'!$A$23:$A$91,'Format Engine'!$C$4,'Format Engine'!$F$23:$F$91,$B7,'Format Engine'!$D$23:$D$91,"<>P"))>0,1,0))
A8: ='Teams Master'!C6 | B8: ='Teams Master'!E6 | C8: =IF(B8="","",LEFT(B8,LEN(B8)-1)) | D8: =SUMIFS('Games Schedule'!$U$5:$U$31,'Games Schedule'!$L$5:$L$31,$B8,'Games Schedule'!$J$5:$J$31,"<>P")+SUMIFS('Games Schedule'!$V$5:$V$31,'Games Schedule'!$M$5:$M$31,$B8,'Games Schedule'!$J$5:$J$31,"<>P") | E8: =SUMIFS('Games Schedule'!$S$5:$S$31,'Games Schedule'!$L$5:$L$31,$B8,'Games Schedule'!$J$5:$J$31,"<>P")+SUMIFS('Games Schedule'!$T$5:$T$31,'Games Schedule'!$M$5:$M$31,$B8,'Games Schedule'!$J$5:$J$31,"<>P") | F8: =SUMIFS('Games Schedule'!$T$5:$T$31,'Games Schedule'!$L$5:$L$31,$B8,'Games Schedule'!$J$5:$J$31,"<>P")+SUMIFS('Games Schedule'!$S$5:$S$31,'Games Schedule'!$M$5:$M$31,$B8,'Games Schedule'!$J$5:$J$31,"<>P") | G8: =E8-F8 | H8: =D8*1000+G8 | I8: {=IF($C8="","",IF($K8=0,"",SUMPRODUCT(($C$4:$C$16=$C8)*($K$4:$K$16=1)*($H$4:$H$16>$H8))+SUMPRODUCT(($C$4:$C$16=$C8)*($K$4:$K$16=1)*($H$4:$H$16=$H8)*(ROW($H$4:$H$16)<ROW($H8)))+1))} | J8: =IF($C8="","",IF($K8=0,"",$C8&I8)) | K8: =IF($B8="","",IF((COUNTIFS('Format Engine'!$A$23:$A$91,'Format Engine'!$C$4,'Format Engine'!$E$23:$E$91,$B8,'Format Engine'!$D$23:$D$91,"<>P")+COUNTIFS('Format Engine'!$A$23:$A$91,'Format Engine'!$C$4,'Format Engine'!$F$23:$F$91,$B8,'Format Engine'!$D$23:$D$91,"<>P"))>0,1,0))
A9: ='Teams Master'!C7 | B9: ='Teams Master'!E7 | C9: =IF(B9="","",LEFT(B9,LEN(B9)-1)) | D9: =SUMIFS('Games Schedule'!$U$5:$U$31,'Games Schedule'!$L$5:$L$31,$B9,'Games Schedule'!$J$5:$J$31,"<>P")+SUMIFS('Games Schedule'!$V$5:$V$31,'Games Schedule'!$M$5:$M$31,$B9,'Games Schedule'!$J$5:$J$31,"<>P") | E9: =SUMIFS('Games Schedule'!$S$5:$S$31,'Games Schedule'!$L$5:$L$31,$B9,'Games Schedule'!$J$5:$J$31,"<>P")+SUMIFS('Games Schedule'!$T$5:$T$31,'Games Schedule'!$M$5:$M$31,$B9,'Games Schedule'!$J$5:$J$31,"<>P") | F9: =SUMIFS('Games Schedule'!$T$5:$T$31,'Games Schedule'!$L$5:$L$31,$B9,'Games Schedule'!$J$5:$J$31,"<>P")+SUMIFS('Games Schedule'!$S$5:$S$31,'Games Schedule'!$M$5:$M$31,$B9,'Games Schedule'!$J$5:$J$31,"<>P") | G9: =E9-F9 | H9: =D9*1000+G9 | I9: {=IF($C9="","",IF($K9=0,"",SUMPRODUCT(($C$4:$C$16=$C9)*($K$4:$K$16=1)*($H$4:$H$16>$H9))+SUMPRODUCT(($C$4:$C$16=$C9)*($K$4:$K$16=1)*($H$4:$H$16=$H9)*(ROW($H$4:$H$16)<ROW($H9)))+1))} | J9: =IF($C9="","",IF($K9=0,"",$C9&I9)) | K9: =IF($B9="","",IF((COUNTIFS('Format Engine'!$A$23:$A$91,'Format Engine'!$C$4,'Format Engine'!$E$23:$E$91,$B9,'Format Engine'!$D$23:$D$91,"<>P")+COUNTIFS('Format Engine'!$A$23:$A$91,'Format Engine'!$C$4,'Format Engine'!$F$23:$F$91,$B9,'Format Engine'!$D$23:$D$91,"<>P"))>0,1,0))
A10: ='Teams Master'!C8 | B10: ='Teams Master'!E8 | C10: =IF(B10="","",LEFT(B10,LEN(B10)-1)) | D10: =SUMIFS('Games Schedule'!$U$5:$U$31,'Games Schedule'!$L$5:$L$31,$B10,'Games Schedule'!$J$5:$J$31,"<>P")+SUMIFS('Games Schedule'!$V$5:$V$31,'Games Schedule'!$M$5:$M$31,$B10,'Games Schedule'!$J$5:$J$31,"<>P") | E10: =SUMIFS('Games Schedule'!$S$5:$S$31,'Games Schedule'!$L$5:$L$31,$B10,'Games Schedule'!$J$5:$J$31,"<>P")+SUMIFS('Games Schedule'!$T$5:$T$31,'Games Schedule'!$M$5:$M$31,$B10,'Games Schedule'!$J$5:$J$31,"<>P") | F10: =SUMIFS('Games Schedule'!$T$5:$T$31,'Games Schedule'!$L$5:$L$31,$B10,'Games Schedule'!$J$5:$J$31,"<>P")+SUMIFS('Games Schedule'!$S$5:$S$31,'Games Schedule'!$M$5:$M$31,$B10,'Games Schedule'!$J$5:$J$31,"<>P") | G10: =E10-F10 | H10: =D10*1000+G10 | I10: {=IF($C10="","",IF($K10=0,"",SUMPRODUCT(($C$4:$C$16=$C10)*($K$4:$K$16=1)*($H$4:$H$16>$H10))+SUMPRODUCT(($C$4:$C$16=$C10)*($K$4:$K$16=1)*($H$4:$H$16=$H10)*(ROW($H$4:$H$16)<ROW($H10)))+1))} | J10: =IF($C10="","",IF($K10=0,"",$C10&I10)) | K10: =IF($B10="","",IF((COUNTIFS('Format Engine'!$A$23:$A$91,'Format Engine'!$C$4,'Format Engine'!$E$23:$E$91,$B10,'Format Engine'!$D$23:$D$91,"<>P")+COUNTIFS('Format Engine'!$A$23:$A$91,'Format Engine'!$C$4,'Format Engine'!$F$23:$F$91,$B10,'Format Engine'!$D$23:$D$91,"<>P"))>0,1,0))
A11: ='Teams Master'!C9 | B11: ='Teams Master'!E9 | C11: =IF(B11="","",LEFT(B11,LEN(B11)-1)) | D11: =SUMIFS('Games Schedule'!$U$5:$U$31,'Games Schedule'!$L$5:$L$31,$B11,'Games Schedule'!$J$5:$J$31,"<>P")+SUMIFS('Games Schedule'!$V$5:$V$31,'Games Schedule'!$M$5:$M$31,$B11,'Games Schedule'!$J$5:$J$31,"<>P") | E11: =SUMIFS('Games Schedule'!$S$5:$S$31,'Games Schedule'!$L$5:$L$31,$B11,'Games Schedule'!$J$5:$J$31,"<>P")+SUMIFS('Games Schedule'!$T$5:$T$31,'Games Schedule'!$M$5:$M$31,$B11,'Games Schedule'!$J$5:$J$31,"<>P") | F11: =SUMIFS('Games Schedule'!$T$5:$T$31,'Games Schedule'!$L$5:$L$31,$B11,'Games Schedule'!$J$5:$J$31,"<>P")+SUMIFS('Games Schedule'!$S$5:$S$31,'Games Schedule'!$M$5:$M$31,$B11,'Games Schedule'!$J$5:$J$31,"<>P") | G11: =E11-F11 | H11: =D11*1000+G11 | I11: {=IF($C11="","",IF($K11=0,"",SUMPRODUCT(($C$4:$C$16=$C11)*($K$4:$K$16=1)*($H$4:$H$16>$H11))+SUMPRODUCT(($C$4:$C$16=$C11)*($K$4:$K$16=1)*($H$4:$H$16=$H11)*(ROW($H$4:$H$16)<ROW($H11)))+1))} | J11: =IF($C11="","",IF($K11=0,"",$C11&I11)) | K11: =IF($B11="","",IF((COUNTIFS('Format Engine'!$A$23:$A$91,'Format Engine'!$C$4,'Format Engine'!$E$23:$E$91,$B11,'Format Engine'!$D$23:$D$91,"<>P")+COUNTIFS('Format Engine'!$A$23:$A$91,'Format Engine'!$C$4,'Format Engine'!$F$23:$F$91,$B11,'Format Engine'!$D$23:$D$91,"<>P"))>0,1,0))
A12: ='Teams Master'!C10 | B12: ='Teams Master'!E10 | C12: =IF(B12="","",LEFT(B12,LEN(B12)-1)) | D12: =SUMIFS('Games Schedule'!$U$5:$U$31,'Games Schedule'!$L$5:$L$31,$B12,'Games Schedule'!$J$5:$J$31,"<>P")+SUMIFS('Games Schedule'!$V$5:$V$31,'Games Schedule'!$M$5:$M$31,$B12,'Games Schedule'!$J$5:$J$31,"<>P") | E12: =SUMIFS('Games Schedule'!$S$5:$S$31,'Games Schedule'!$L$5:$L$31,$B12,'Games Schedule'!$J$5:$J$31,"<>P")+SUMIFS('Games Schedule'!$T$5:$T$31,'Games Schedule'!$M$5:$M$31,$B12,'Games Schedule'!$J$5:$J$31,"<>P") | F12: =SUMIFS('Games Schedule'!$T$5:$T$31,'Games Schedule'!$L$5:$L$31,$B12,'Games Schedule'!$J$5:$J$31,"<>P")+SUMIFS('Games Schedule'!$S$5:$S$31,'Games Schedule'!$M$5:$M$31,$B12,'Games Schedule'!$J$5:$J$31,"<>P") | G12: =E12-F12 | H12: =D12*1000+G12 | I12: {=IF($C12="","",IF($K12=0,"",SUMPRODUCT(($C$4:$C$16=$C12)*($K$4:$K$16=1)*($H$4:$H$16>$H12))+SUMPRODUCT(($C$4:$C$16=$C12)*($K$4:$K$16=1)*($H$4:$H$16=$H12)*(ROW($H$4:$H$16)<ROW($H12)))+1))} | J12: =IF($C12="","",IF($K12=0,"",$C12&I12)) | K12: =IF($B12="","",IF((COUNTIFS('Format Engine'!$A$23:$A$91,'Format Engine'!$C$4,'Format Engine'!$E$23:$E$91,$B12,'Format Engine'!$D$23:$D$91,"<>P")+COUNTIFS('Format Engine'!$A$23:$A$91,'Format Engine'!$C$4,'Format Engine'!$F$23:$F$91,$B12,'Format Engine'!$D$23:$D$91,"<>P"))>0,1,0))
A13: ='Teams Master'!C11 | B13: ='Teams Master'!E11 | C13: =IF(B13="","",LEFT(B13,LEN(B13)-1)) | D13: =SUMIFS('Games Schedule'!$U$5:$U$31,'Games Schedule'!$L$5:$L$31,$B13,'Games Schedule'!$J$5:$J$31,"<>P")+SUMIFS('Games Schedule'!$V$5:$V$31,'Games Schedule'!$M$5:$M$31,$B13,'Games Schedule'!$J$5:$J$31,"<>P") | E13: =SUMIFS('Games Schedule'!$S$5:$S$31,'Games Schedule'!$L$5:$L$31,$B13,'Games Schedule'!$J$5:$J$31,"<>P")+SUMIFS('Games Schedule'!$T$5:$T$31,'Games Schedule'!$M$5:$M$31,$B13,'Games Schedule'!$J$5:$J$31,"<>P") | F13: =SUMIFS('Games Schedule'!$T$5:$T$31,'Games Schedule'!$L$5:$L$31,$B13,'Games Schedule'!$J$5:$J$31,"<>P")+SUMIFS('Games Schedule'!$S$5:$S$31,'Games Schedule'!$M$5:$M$31,$B13,'Games Schedule'!$J$5:$J$31,"<>P") | G13: =E13-F13 | H13: =D13*1000+G13 | I13: {=IF($C13="","",IF($K13=0,"",SUMPRODUCT(($C$4:$C$16=$C13)*($K$4:$K$16=1)*($H$4:$H$16>$H13))+SUMPRODUCT(($C$4:$C$16=$C13)*($K$4:$K$16=1)*($H$4:$H$16=$H13)*(ROW($H$4:$H$16)<ROW($H13)))+1))} | J13: =IF($C13="","",IF($K13=0,"",$C13&I13)) | K13: =IF($B13="","",IF((COUNTIFS('Format Engine'!$A$23:$A$91,'Format Engine'!$C$4,'Format Engine'!$E$23:$E$91,$B13,'Format Engine'!$D$23:$D$91,"<>P")+COUNTIFS('Format Engine'!$A$23:$A$91,'Format Engine'!$C$4,'Format Engine'!$F$23:$F$91,$B13,'Format Engine'!$D$23:$D$91,"<>P"))>0,1,0))
A14: ='Teams Master'!C12 | B14: ='Teams Master'!E12 | C14: =IF(B14="","",LEFT(B14,LEN(B14)-1)) | D14: =SUMIFS('Games Schedule'!$U$5:$U$31,'Games Schedule'!$L$5:$L$31,$B14,'Games Schedule'!$J$5:$J$31,"<>P")+SUMIFS('Games Schedule'!$V$5:$V$31,'Games Schedule'!$M$5:$M$31,$B14,'Games Schedule'!$J$5:$J$31,"<>P") | E14: =SUMIFS('Games Schedule'!$S$5:$S$31,'Games Schedule'!$L$5:$L$31,$B14,'Games Schedule'!$J$5:$J$31,"<>P")+SUMIFS('Games Schedule'!$T$5:$T$31,'Games Schedule'!$M$5:$M$31,$B14,'Games Schedule'!$J$5:$J$31,"<>P") | F14: =SUMIFS('Games Schedule'!$T$5:$T$31,'Games Schedule'!$L$5:$L$31,$B14,'Games Schedule'!$J$5:$J$31,"<>P")+SUMIFS('Games Schedule'!$S$5:$S$31,'Games Schedule'!$M$5:$M$31,$B14,'Games Schedule'!$J$5:$J$31,"<>P") | G14: =E14-F14 | H14: =D14*1000+G14 | I14: {=IF($C14="","",IF($K14=0,"",SUMPRODUCT(($C$4:$C$16=$C14)*($K$4:$K$16=1)*($H$4:$H$16>$H14))+SUMPRODUCT(($C$4:$C$16=$C14)*($K$4:$K$16=1)*($H$4:$H$16=$H14)*(ROW($H$4:$H$16)<ROW($H14)))+1))} | J14: =IF($C14="","",IF($K14=0,"",$C14&I14)) | K14: =IF($B14="","",IF((COUNTIFS('Format Engine'!$A$23:$A$91,'Format Engine'!$C$4,'Format Engine'!$E$23:$E$91,$B14,'Format Engine'!$D$23:$D$91,"<>P")+COUNTIFS('Format Engine'!$A$23:$A$91,'Format Engine'!$C$4,'Format Engine'!$F$23:$F$91,$B14,'Format Engine'!$D$23:$D$91,"<>P"))>0,1,0))
A15: ='Teams Master'!C13 | B15: ='Teams Master'!E13 | C15: =IF(B15="","",LEFT(B15,LEN(B15)-1)) | D15: =SUMIFS('Games Schedule'!$U$5:$U$31,'Games Schedule'!$L$5:$L$31,$B15,'Games Schedule'!$J$5:$J$31,"<>P")+SUMIFS('Games Schedule'!$V$5:$V$31,'Games Schedule'!$M$5:$M$31,$B15,'Games Schedule'!$J$5:$J$31,"<>P") | E15: =SUMIFS('Games Schedule'!$S$5:$S$31,'Games Schedule'!$L$5:$L$31,$B15,'Games Schedule'!$J$5:$J$31,"<>P")+SUMIFS('Games Schedule'!$T$5:$T$31,'Games Schedule'!$M$5:$M$31,$B15,'Games Schedule'!$J$5:$J$31,"<>P") | F15: =SUMIFS('Games Schedule'!$T$5:$T$31,'Games Schedule'!$L$5:$L$31,$B15,'Games Schedule'!$J$5:$J$31,"<>P")+SUMIFS('Games Schedule'!$S$5:$S$31,'Games Schedule'!$M$5:$M$31,$B15,'Games Schedule'!$J$5:$J$31,"<>P") | G15: =E15-F15 | H15: =D15*1000+G15 | I15: {=IF($C15="","",IF($K15=0,"",SUMPRODUCT(($C$4:$C$16=$C15)*($K$4:$K$16=1)*($H$4:$H$16>$H15))+SUMPRODUCT(($C$4:$C$16=$C15)*($K$4:$K$16=1)*($H$4:$H$16=$H15)*(ROW($H$4:$H$16)<ROW($H15)))+1))} | J15: =IF($C15="","",IF($K15=0,"",$C15&I15)) | K15: =IF($B15="","",IF((COUNTIFS('Format Engine'!$A$23:$A$91,'Format Engine'!$C$4,'Format Engine'!$E$23:$E$91,$B15,'Format Engine'!$D$23:$D$91,"<>P")+COUNTIFS('Format Engine'!$A$23:$A$91,'Format Engine'!$C$4,'Format Engine'!$F$23:$F$91,$B15,'Format Engine'!$D$23:$D$91,"<>P"))>0,1,0))
A16: ='Teams Master'!C14 | B16: ='Teams Master'!E14 | C16: =IF(B16="","",LEFT(B16,LEN(B16)-1)) | D16: =SUMIFS('Games Schedule'!$U$5:$U$31,'Games Schedule'!$L$5:$L$31,$B16,'Games Schedule'!$J$5:$J$31,"<>P")+SUMIFS('Games Schedule'!$V$5:$V$31,'Games Schedule'!$M$5:$M$31,$B16,'Games Schedule'!$J$5:$J$31,"<>P") | E16: =SUMIFS('Games Schedule'!$S$5:$S$31,'Games Schedule'!$L$5:$L$31,$B16,'Games Schedule'!$J$5:$J$31,"<>P")+SUMIFS('Games Schedule'!$T$5:$T$31,'Games Schedule'!$M$5:$M$31,$B16,'Games Schedule'!$J$5:$J$31,"<>P") | F16: =SUMIFS('Games Schedule'!$T$5:$T$31,'Games Schedule'!$L$5:$L$31,$B16,'Games Schedule'!$J$5:$J$31,"<>P")+SUMIFS('Games Schedule'!$S$5:$S$31,'Games Schedule'!$M$5:$M$31,$B16,'Games Schedule'!$J$5:$J$31,"<>P") | G16: =E16-F16 | H16: =D16*1000+G16 | I16: {=IF($C16="","",IF($K16=0,"",SUMPRODUCT(($C$4:$C$16=$C16)*($K$4:$K$16=1)*($H$4:$H$16>$H16))+SUMPRODUCT(($C$4:$C$16=$C16)*($K$4:$K$16=1)*($H$4:$H$16=$H16)*(ROW($H$4:$H$16)<ROW($H16)))+1))} | J16: =IF($C16="","",IF($K16=0,"",$C16&I16)) | K16: =IF($B16="","",IF((COUNTIFS('Format Engine'!$A$23:$A$91,'Format Engine'!$C$4,'Format Engine'!$E$23:$E$91,$B16,'Format Engine'!$D$23:$D$91,"<>P")+COUNTIFS('Format Engine'!$A$23:$A$91,'Format Engine'!$C$4,'Format Engine'!$F$23:$F$91,$B16,'Format Engine'!$D$23:$D$91,"<>P"))>0,1,0))

Sheet Teams Master
A1: TeamID | B1: Team Name | C1: Short Name | D1: Division | E1: Group Code | F1: Jersey Color Home | G1: Jersey Color Away | H1: Contact Name | I1: Contact Email | J1: Contact Phone | K1: Reg Status | L1: ⚠️ Rows fill automatically from Registration 2027 (Status = Fully Registered or Host Registered). Give each team a Short Name + Jerseys in the Team Styles table (O:R) → | M1: Code Check | O1: Team Name | P1: Short Name | Q1: Jersey Home | R1: Jersey Away
A2: =IF($C2="","",IF($D2="Men","M"&COUNTIF($D$2:$D2,"Men"),"W"&COUNTIF($D$2:$D2,"Women"))) | B2: =IFERROR(INDEX('Registration 2027'!$A$2:$A$45,MATCH(ROW()-1,'Registration 2027'!$U$2:$U$53,0)),"") | C2: =IF($B2="","",IFERROR(_xlfn.XLOOKUP($B2,TeamStyles[Team Name],TeamStyles[Short Name]),"⚠ add to Team Styles")) | D2: =IFERROR(INDEX('Registration 2027'!$B$2:$B$45,MATCH(ROW()-1,'Registration 2027'!$U$2:$U$53,0)),"") | E2: A1 | F2: =IF($B2="","",IFERROR(_xlfn.XLOOKUP($B2,TeamStyles[Team Name],TeamStyles[Jersey Home]),"⚠ add to Team Styles")) | G2: =IF($B2="","",IFERROR(_xlfn.XLOOKUP($B2,TeamStyles[Team Name],TeamStyles[Jersey Away]),"⚠ add to Team Styles")) | H2: =IFERROR(_xlfn.LET(_xlpm.v,INDEX('Registration 2027'!$K$2:$K$45,MATCH(ROW()-1,'Registration 2027'!$U$2:$U$53,0)),IF(OR(_xlpm.v=0,_xlpm.v=""),"",_xlpm.v)),"") | I2: =IFERROR(_xlfn.LET(_xlpm.v,INDEX('Registration 2027'!$L$2:$L$45,MATCH(ROW()-1,'Registration 2027'!$U$2:$U$53,0)),IF(OR(_xlpm.v=0,_xlpm.v=""),"",_xlpm.v)),"") | J2: =IFERROR(_xlfn.LET(_xlpm.v,INDEX('Registration 2027'!$N$2:$N$45,MATCH(ROW()-1,'Registration 2027'!$U$2:$U$53,0)),IF(OR(_xlpm.v=0,_xlpm.v=""),"",_xlpm.v)),"") | K2: =IFERROR(INDEX('Registration 2027'!$J$2:$J$45,MATCH(ROW()-1,'Registration 2027'!$U$2:$U$53,0)),"") | M2: =IF(E2="","",IF(COUNTIF($E$2:$E$14,E2)>1,"DUPLICATE","OK")) | O2: Harbor HC | P2: HAR | Q2: Navy | R2: White
A3: =IF($C3="","",IF($D3="Men","M"&COUNTIF($D$2:$D3,"Men"),"W"&COUNTIF($D$2:$D3,"Women"))) | B3: =IFERROR(INDEX('Registration 2027'!$A$2:$A$45,MATCH(ROW()-1,'Registration 2027'!$U$2:$U$53,0)),"") | C3: =IF($B3="","",IFERROR(_xlfn.XLOOKUP($B3,TeamStyles[Team Name],TeamStyles[Short Name]),"⚠ add to Team Styles")) | D3: =IFERROR(INDEX('Registration 2027'!$B$2:$B$45,MATCH(ROW()-1,'Registration 2027'!$U$2:$U$53,0)),"") | E3: A3 | F3: =IF($B3="","",IFERROR(_xlfn.XLOOKUP($B3,TeamStyles[Team Name],TeamStyles[Jersey Home]),"⚠ add to Team Styles")) | G3: =IF($B3="","",IFERROR(_xlfn.XLOOKUP($B3,TeamStyles[Team Name],TeamStyles[Jersey Away]),"⚠ add to Team Styles")) | H3: =IFERROR(_xlfn.LET(_xlpm.v,INDEX('Registration 2027'!$K$2:$K$45,MATCH(ROW()-1,'Registration 2027'!$U$2:$U$53,0)),IF(OR(_xlpm.v=0,_xlpm.v=""),"",_xlpm.v)),"") | I3: =IFERROR(_xlfn.LET(_xlpm.v,INDEX('Registration 2027'!$L$2:$L$45,MATCH(ROW()-1,'Registration 2027'!$U$2:$U$53,0)),IF(OR(_xlpm.v=0,_xlpm.v=""),"",_xlpm.v)),"") | J3: =IFERROR(_xlfn.LET(_xlpm.v,INDEX('Registration 2027'!$N$2:$N$45,MATCH(ROW()-1,'Registration 2027'!$U$2:$U$53,0)),IF(OR(_xlpm.v=0,_xlpm.v=""),"",_xlpm.v)),"") | K3: =IFERROR(INDEX('Registration 2027'!$J$2:$J$45,MATCH(ROW()-1,'Registration 2027'!$U$2:$U$53,0)),"") | M3: =IF(E3="","",IF(COUNTIF($E$2:$E$14,E3)>1,"DUPLICATE","OK")) | O3: Mesa Valley | P3: MES | Q3: Red | R3: White
A4: =IF($C4="","",IF($D4="Men","M"&COUNTIF($D$2:$D4,"Men"),"W"&COUNTIF($D$2:$D4,"Women"))) | B4: =IFERROR(INDEX('Registration 2027'!$A$2:$A$45,MATCH(ROW()-1,'Registration 2027'!$U$2:$U$53,0)),"") | C4: =IF($B4="","",IFERROR(_xlfn.XLOOKUP($B4,TeamStyles[Team Name],TeamStyles[Short Name]),"⚠ add to Team Styles")) | D4: =IFERROR(INDEX('Registration 2027'!$B$2:$B$45,MATCH(ROW()-1,'Registration 2027'!$U$2:$U$53,0)),"") | E4: B1 | F4: =IF($B4="","",IFERROR(_xlfn.XLOOKUP($B4,TeamStyles[Team Name],TeamStyles[Jersey Home]),"⚠ add to Team Styles")) | G4: =IF($B4="","",IFERROR(_xlfn.XLOOKUP($B4,TeamStyles[Team Name],TeamStyles[Jersey Away]),"⚠ add to Team Styles")) | H4: =IFERROR(_xlfn.LET(_xlpm.v,INDEX('Registration 2027'!$K$2:$K$45,MATCH(ROW()-1,'Registration 2027'!$U$2:$U$53,0)),IF(OR(_xlpm.v=0,_xlpm.v=""),"",_xlpm.v)),"") | I4: =IFERROR(_xlfn.LET(_xlpm.v,INDEX('Registration 2027'!$L$2:$L$45,MATCH(ROW()-1,'Registration 2027'!$U$2:$U$53,0)),IF(OR(_xlpm.v=0,_xlpm.v=""),"",_xlpm.v)),"") | J4: =IFERROR(_xlfn.LET(_xlpm.v,INDEX('Registration 2027'!$N$2:$N$45,MATCH(ROW()-1,'Registration 2027'!$U$2:$U$53,0)),IF(OR(_xlpm.v=0,_xlpm.v=""),"",_xlpm.v)),"") | K4: =IFERROR(INDEX('Registration 2027'!$J$2:$J$45,MATCH(ROW()-1,'Registration 2027'!$U$2:$U$53,0)),"") | M4: =IF(E4="","",IF(COUNTIF($E$2:$E$14,E4)>1,"DUPLICATE","OK")) | O4: Redwood United | P4: RED | Q4: Green | R4: White
A5: =IF($C5="","",IF($D5="Men","M"&COUNTIF($D$2:$D5,"Men"),"W"&COUNTIF($D$2:$D5,"Women"))) | B5: =IFERROR(INDEX('Registration 2027'!$A$2:$A$45,MATCH(ROW()-1,'Registration 2027'!$U$2:$U$53,0)),"") | C5: =IF($B5="","",IFERROR(_xlfn.XLOOKUP($B5,TeamStyles[Team Name],TeamStyles[Short Name]),"⚠ add to Team Styles")) | D5: =IFERROR(INDEX('Registration 2027'!$B$2:$B$45,MATCH(ROW()-1,'Registration 2027'!$U$2:$U$53,0)),"") | E5: B3 | F5: =IF($B5="","",IFERROR(_xlfn.XLOOKUP($B5,TeamStyles[Team Name],TeamStyles[Jersey Home]),"⚠ add to Team Styles")) | G5: =IF($B5="","",IFERROR(_xlfn.XLOOKUP($B5,TeamStyles[Team Name],TeamStyles[Jersey Away]),"⚠ add to Team Styles")) | H5: =IFERROR(_xlfn.LET(_xlpm.v,INDEX('Registration 2027'!$K$2:$K$45,MATCH(ROW()-1,'Registration 2027'!$U$2:$U$53,0)),IF(OR(_xlpm.v=0,_xlpm.v=""),"",_xlpm.v)),"") | I5: =IFERROR(_xlfn.LET(_xlpm.v,INDEX('Registration 2027'!$L$2:$L$45,MATCH(ROW()-1,'Registration 2027'!$U$2:$U$53,0)),IF(OR(_xlpm.v=0,_xlpm.v=""),"",_xlpm.v)),"") | J5: =IFERROR(_xlfn.LET(_xlpm.v,INDEX('Registration 2027'!$N$2:$N$45,MATCH(ROW()-1,'Registration 2027'!$U$2:$U$53,0)),IF(OR(_xlpm.v=0,_xlpm.v=""),"",_xlpm.v)),"") | K5: =IFERROR(INDEX('Registration 2027'!$J$2:$J$45,MATCH(ROW()-1,'Registration 2027'!$U$2:$U$53,0)),"") | M5: =IF(E5="","",IF(COUNTIF($E$2:$E$14,E5)>1,"DUPLICATE","OK")) | O5: Pacific Coast | P5: PAC | Q5: Blue | R5: Yellow
A6: =IF($C6="","",IF($D6="Men","M"&COUNTIF($D$2:$D6,"Men"),"W"&COUNTIF($D$2:$D6,"Women"))) | B6: =IFERROR(INDEX('Registration 2027'!$A$2:$A$45,MATCH(ROW()-1,'Registration 2027'!$U$2:$U$53,0)),"") | C6: =IF($B6="","",IFERROR(_xlfn.XLOOKUP($B6,TeamStyles[Team Name],TeamStyles[Short Name]),"⚠ add to Team Styles")) | D6: =IFERROR(INDEX('Registration 2027'!$B$2:$B$45,MATCH(ROW()-1,'Registration 2027'!$U$2:$U$53,0)),"") | E6: B4 | F6: =IF($B6="","",IFERROR(_xlfn.XLOOKUP($B6,TeamStyles[Team Name],TeamStyles[Jersey Home]),"⚠ add to Team Styles")) | G6: =IF($B6="","",IFERROR(_xlfn.XLOOKUP($B6,TeamStyles[Team Name],TeamStyles[Jersey Away]),"⚠ add to Team Styles")) | H6: =IFERROR(_xlfn.LET(_xlpm.v,INDEX('Registration 2027'!$K$2:$K$45,MATCH(ROW()-1,'Registration 2027'!$U$2:$U$53,0)),IF(OR(_xlpm.v=0,_xlpm.v=""),"",_xlpm.v)),"") | I6: =IFERROR(_xlfn.LET(_xlpm.v,INDEX('Registration 2027'!$L$2:$L$45,MATCH(ROW()-1,'Registration 2027'!$U$2:$U$53,0)),IF(OR(_xlpm.v=0,_xlpm.v=""),"",_xlpm.v)),"") | J6: =IFERROR(_xlfn.LET(_xlpm.v,INDEX('Registration 2027'!$N$2:$N$45,MATCH(ROW()-1,'Registration 2027'!$U$2:$U$53,0)),IF(OR(_xlpm.v=0,_xlpm.v=""),"",_xlpm.v)),"") | K6: =IFERROR(INDEX('Registration 2027'!$J$2:$J$45,MATCH(ROW()-1,'Registration 2027'!$U$2:$U$53,0)),"") | M6: =IF(E6="","",IF(COUNTIF($E$2:$E$14,E6)>1,"DUPLICATE","OK")) | O6: Summit City | P6: SUM | Q6: Black | R6: Orange
A7: =IF($C7="","",IF($D7="Men","M"&COUNTIF($D$2:$D7,"Men"),"W"&COUNTIF($D$2:$D7,"Women"))) | B7: =IFERROR(INDEX('Registration 2027'!$A$2:$A$45,MATCH(ROW()-1,'Registration 2027'!$U$2:$U$53,0)),"") | C7: =IF($B7="","",IFERROR(_xlfn.XLOOKUP($B7,TeamStyles[Team Name],TeamStyles[Short Name]),"⚠ add to Team Styles")) | D7: =IFERROR(INDEX('Registration 2027'!$B$2:$B$45,MATCH(ROW()-1,'Registration 2027'!$U$2:$U$53,0)),"") | E7: A2 | F7: =IF($B7="","",IFERROR(_xlfn.XLOOKUP($B7,TeamStyles[Team Name],TeamStyles[Jersey Home]),"⚠ add to Team Styles")) | G7: =IF($B7="","",IFERROR(_xlfn.XLOOKUP($B7,TeamStyles[Team Name],TeamStyles[Jersey Away]),"⚠ add to Team Styles")) | H7: =IFERROR(_xlfn.LET(_xlpm.v,INDEX('Registration 2027'!$K$2:$K$45,MATCH(ROW()-1,'Registration 2027'!$U$2:$U$53,0)),IF(OR(_xlpm.v=0,_xlpm.v=""),"",_xlpm.v)),"") | I7: =IFERROR(_xlfn.LET(_xlpm.v,INDEX('Registration 2027'!$L$2:$L$45,MATCH(ROW()-1,'Registration 2027'!$U$2:$U$53,0)),IF(OR(_xlpm.v=0,_xlpm.v=""),"",_xlpm.v)),"") | J7: =IFERROR(_xlfn.LET(_xlpm.v,INDEX('Registration 2027'!$N$2:$N$45,MATCH(ROW()-1,'Registration 2027'!$U$2:$U$53,0)),IF(OR(_xlpm.v=0,_xlpm.v=""),"",_xlpm.v)),"") | K7: =IFERROR(INDEX('Registration 2027'!$J$2:$J$45,MATCH(ROW()-1,'Registration 2027'!$U$2:$U$53,0)),"") | M7: =IF(E7="","",IF(COUNTIF($E$2:$E$14,E7)>1,"DUPLICATE","OK")) | O7: Lakeside HB | P7: LAK | Q7: Sky Blue | R7: White
A8: =IF($C8="","",IF($D8="Men","M"&COUNTIF($D$2:$D8,"Men"),"W"&COUNTIF($D$2:$D8,"Women"))) | B8: =IFERROR(INDEX('Registration 2027'!$A$2:$A$45,MATCH(ROW()-1,'Registration 2027'!$U$2:$U$53,0)),"") | C8: =IF($B8="","",IFERROR(_xlfn.XLOOKUP($B8,TeamStyles[Team Name],TeamStyles[Short Name]),"⚠ add to Team Styles")) | D8: =IFERROR(INDEX('Registration 2027'!$B$2:$B$45,MATCH(ROW()-1,'Registration 2027'!$U$2:$U$53,0)),"") | E8: B2 | F8: =IF($B8="","",IFERROR(_xlfn.XLOOKUP($B8,TeamStyles[Team Name],TeamStyles[Jersey Home]),"⚠ add to Team Styles")) | G8: =IF($B8="","",IFERROR(_xlfn.XLOOKUP($B8,TeamStyles[Team Name],TeamStyles[Jersey Away]),"⚠ add to Team Styles")) | H8: =IFERROR(_xlfn.LET(_xlpm.v,INDEX('Registration 2027'!$K$2:$K$45,MATCH(ROW()-1,'Registration 2027'!$U$2:$U$53,0)),IF(OR(_xlpm.v=0,_xlpm.v=""),"",_xlpm.v)),"") | I8: =IFERROR(_xlfn.LET(_xlpm.v,INDEX('Registration 2027'!$L$2:$L$45,MATCH(ROW()-1,'Registration 2027'!$U$2:$U$53,0)),IF(OR(_xlpm.v=0,_xlpm.v=""),"",_xlpm.v)),"") | J8: =IFERROR(_xlfn.LET(_xlpm.v,INDEX('Registration 2027'!$N$2:$N$45,MATCH(ROW()-1,'Registration 2027'!$U$2:$U$53,0)),IF(OR(_xlpm.v=0,_xlpm.v=""),"",_xlpm.v)),"") | K8: =IFERROR(INDEX('Registration 2027'!$J$2:$J$45,MATCH(ROW()-1,'Registration 2027'!$U$2:$U$53,0)),"") | M8: =IF(E8="","",IF(COUNTIF($E$2:$E$14,E8)>1,"DUPLICATE","OK")) | O8: Canyon Ridge HC | P8: CAN | Q8: Maroon | R8: Gold
A9: =IF($C9="","",IF($D9="Men","M"&COUNTIF($D$2:$D9,"Men"),"W"&COUNTIF($D$2:$D9,"Women"))) | B9: =IFERROR(INDEX('Registration 2027'!$A$2:$A$45,MATCH(ROW()-1,'Registration 2027'!$U$2:$U$53,0)),"") | C9: =IF($B9="","",IFERROR(_xlfn.XLOOKUP($B9,TeamStyles[Team Name],TeamStyles[Short Name]),"⚠ add to Team Styles")) | D9: =IFERROR(INDEX('Registration 2027'!$B$2:$B$45,MATCH(ROW()-1,'Registration 2027'!$U$2:$U$53,0)),"") | E9: A4 | F9: =IF($B9="","",IFERROR(_xlfn.XLOOKUP($B9,TeamStyles[Team Name],TeamStyles[Jersey Home]),"⚠ add to Team Styles")) | G9: =IF($B9="","",IFERROR(_xlfn.XLOOKUP($B9,TeamStyles[Team Name],TeamStyles[Jersey Away]),"⚠ add to Team Styles")) | H9: =IFERROR(_xlfn.LET(_xlpm.v,INDEX('Registration 2027'!$K$2:$K$45,MATCH(ROW()-1,'Registration 2027'!$U$2:$U$53,0)),IF(OR(_xlpm.v=0,_xlpm.v=""),"",_xlpm.v)),"") | I9: =IFERROR(_xlfn.LET(_xlpm.v,INDEX('Registration 2027'!$L$2:$L$45,MATCH(ROW()-1,'Registration 2027'!$U$2:$U$53,0)),IF(OR(_xlpm.v=0,_xlpm.v=""),"",_xlpm.v)),"") | J9: =IFERROR(_xlfn.LET(_xlpm.v,INDEX('Registration 2027'!$N$2:$N$45,MATCH(ROW()-1,'Registration 2027'!$U$2:$U$53,0)),IF(OR(_xlpm.v=0,_xlpm.v=""),"",_xlpm.v)),"") | K9: =IFERROR(INDEX('Registration 2027'!$J$2:$J$45,MATCH(ROW()-1,'Registration 2027'!$U$2:$U$53,0)),"") | M9: =IF(E9="","",IF(COUNTIF($E$2:$E$14,E9)>1,"DUPLICATE","OK")) | O9: Northwind HC | P9: NOR | Q9: Gray | R9: Black
A10: =IF($C10="","",IF($D10="Men","M"&COUNTIF($D$2:$D10,"Men"),"W"&COUNTIF($D$2:$D10,"Women"))) | B10: =IFERROR(INDEX('Registration 2027'!$A$2:$A$45,MATCH(ROW()-1,'Registration 2027'!$U$2:$U$53,0)),"") | C10: =IF($B10="","",IFERROR(_xlfn.XLOOKUP($B10,TeamStyles[Team Name],TeamStyles[Short Name]),"⚠ add to Team Styles")) | D10: =IFERROR(INDEX('Registration 2027'!$B$2:$B$45,MATCH(ROW()-1,'Registration 2027'!$U$2:$U$53,0)),"") | E10: W1 | F10: =IF($B10="","",IFERROR(_xlfn.XLOOKUP($B10,TeamStyles[Team Name],TeamStyles[Jersey Home]),"⚠ add to Team Styles")) | G10: =IF($B10="","",IFERROR(_xlfn.XLOOKUP($B10,TeamStyles[Team Name],TeamStyles[Jersey Away]),"⚠ add to Team Styles")) | H10: =IFERROR(_xlfn.LET(_xlpm.v,INDEX('Registration 2027'!$K$2:$K$45,MATCH(ROW()-1,'Registration 2027'!$U$2:$U$53,0)),IF(OR(_xlpm.v=0,_xlpm.v=""),"",_xlpm.v)),"") | I10: =IFERROR(_xlfn.LET(_xlpm.v,INDEX('Registration 2027'!$L$2:$L$45,MATCH(ROW()-1,'Registration 2027'!$U$2:$U$53,0)),IF(OR(_xlpm.v=0,_xlpm.v=""),"",_xlpm.v)),"") | J10: =IFERROR(_xlfn.LET(_xlpm.v,INDEX('Registration 2027'!$N$2:$N$45,MATCH(ROW()-1,'Registration 2027'!$U$2:$U$53,0)),IF(OR(_xlpm.v=0,_xlpm.v=""),"",_xlpm.v)),"") | K10: =IFERROR(INDEX('Registration 2027'!$J$2:$J$45,MATCH(ROW()-1,'Registration 2027'!$U$2:$U$53,0)),"") | M10: =IF(E10="","",IF(COUNTIF($E$2:$E$14,E10)>1,"DUPLICATE","OK")) | O10: Harbor HC W | P10: HARW | Q10: Navy | R10: White
A11: =IF($C11="","",IF($D11="Men","M"&COUNTIF($D$2:$D11,"Men"),"W"&COUNTIF($D$2:$D11,"Women"))) | B11: =IFERROR(INDEX('Registration 2027'!$A$2:$A$45,MATCH(ROW()-1,'Registration 2027'!$U$2:$U$53,0)),"") | C11: =IF($B11="","",IFERROR(_xlfn.XLOOKUP($B11,TeamStyles[Team Name],TeamStyles[Short Name]),"⚠ add to Team Styles")) | D11: =IFERROR(INDEX('Registration 2027'!$B$2:$B$45,MATCH(ROW()-1,'Registration 2027'!$U$2:$U$53,0)),"") | E11: W3 | F11: =IF($B11="","",IFERROR(_xlfn.XLOOKUP($B11,TeamStyles[Team Name],TeamStyles[Jersey Home]),"⚠ add to Team Styles")) | G11: =IF($B11="","",IFERROR(_xlfn.XLOOKUP($B11,TeamStyles[Team Name],TeamStyles[Jersey Away]),"⚠ add to Team Styles")) | H11: =IFERROR(_xlfn.LET(_xlpm.v,INDEX('Registration 2027'!$K$2:$K$45,MATCH(ROW()-1,'Registration 2027'!$U$2:$U$53,0)),IF(OR(_xlpm.v=0,_xlpm.v=""),"",_xlpm.v)),"") | I11: =IFERROR(_xlfn.LET(_xlpm.v,INDEX('Registration 2027'!$L$2:$L$45,MATCH(ROW()-1,'Registration 2027'!$U$2:$U$53,0)),IF(OR(_xlpm.v=0,_xlpm.v=""),"",_xlpm.v)),"") | J11: =IFERROR(_xlfn.LET(_xlpm.v,INDEX('Registration 2027'!$N$2:$N$45,MATCH(ROW()-1,'Registration 2027'!$U$2:$U$53,0)),IF(OR(_xlpm.v=0,_xlpm.v=""),"",_xlpm.v)),"") | K11: =IFERROR(INDEX('Registration 2027'!$J$2:$J$45,MATCH(ROW()-1,'Registration 2027'!$U$2:$U$53,0)),"") | M11: =IF(E11="","",IF(COUNTIF($E$2:$E$14,E11)>1,"DUPLICATE","OK")) | O11: Redwood United W | P11: REDW | Q11: Green | R11: White
A12: =IF($C12="","",IF($D12="Men","M"&COUNTIF($D$2:$D12,"Men"),"W"&COUNTIF($D$2:$D12,"Women"))) | B12: =IFERROR(INDEX('Registration 2027'!$A$2:$A$45,MATCH(ROW()-1,'Registration 2027'!$U$2:$U$53,0)),"") | C12: =IF($B12="","",IFERROR(_xlfn.XLOOKUP($B12,TeamStyles[Team Name],TeamStyles[Short Name]),"⚠ add to Team Styles")) | D12: =IFERROR(INDEX('Registration 2027'!$B$2:$B$45,MATCH(ROW()-1,'Registration 2027'!$U$2:$U$53,0)),"") | E12: W2 | F12: =IF($B12="","",IFERROR(_xlfn.XLOOKUP($B12,TeamStyles[Team Name],TeamStyles[Jersey Home]),"⚠ add to Team Styles")) | G12: =IF($B12="","",IFERROR(_xlfn.XLOOKUP($B12,TeamStyles[Team Name],TeamStyles[Jersey Away]),"⚠ add to Team Styles")) | H12: =IFERROR(_xlfn.LET(_xlpm.v,INDEX('Registration 2027'!$K$2:$K$45,MATCH(ROW()-1,'Registration 2027'!$U$2:$U$53,0)),IF(OR(_xlpm.v=0,_xlpm.v=""),"",_xlpm.v)),"") | I12: =IFERROR(_xlfn.LET(_xlpm.v,INDEX('Registration 2027'!$L$2:$L$45,MATCH(ROW()-1,'Registration 2027'!$U$2:$U$53,0)),IF(OR(_xlpm.v=0,_xlpm.v=""),"",_xlpm.v)),"") | J12: =IFERROR(_xlfn.LET(_xlpm.v,INDEX('Registration 2027'!$N$2:$N$45,MATCH(ROW()-1,'Registration 2027'!$U$2:$U$53,0)),IF(OR(_xlpm.v=0,_xlpm.v=""),"",_xlpm.v)),"") | K12: =IFERROR(INDEX('Registration 2027'!$J$2:$J$45,MATCH(ROW()-1,'Registration 2027'!$U$2:$U$53,0)),"") | M12: =IF(E12="","",IF(COUNTIF($E$2:$E$14,E12)>1,"DUPLICATE","OK")) | O12: Desert Storm | P12: DES | Q12: Orange | R12: Black
A13: =IF($C13="","",IF($D13="Men","M"&COUNTIF($D$2:$D13,"Men"),"W"&COUNTIF($D$2:$D13,"Women"))) | B13: =IFERROR(INDEX('Registration 2027'!$A$2:$A$45,MATCH(ROW()-1,'Registration 2027'!$U$2:$U$53,0)),"") | C13: =IF($B13="","",IFERROR(_xlfn.XLOOKUP($B13,TeamStyles[Team Name],TeamStyles[Short Name]),"⚠ add to Team Styles")) | D13: =IFERROR(INDEX('Registration 2027'!$B$2:$B$45,MATCH(ROW()-1,'Registration 2027'!$U$2:$U$53,0)),"") | E13: W4 | F13: =IF($B13="","",IFERROR(_xlfn.XLOOKUP($B13,TeamStyles[Team Name],TeamStyles[Jersey Home]),"⚠ add to Team Styles")) | G13: =IF($B13="","",IFERROR(_xlfn.XLOOKUP($B13,TeamStyles[Team Name],TeamStyles[Jersey Away]),"⚠ add to Team Styles")) | H13: =IFERROR(_xlfn.LET(_xlpm.v,INDEX('Registration 2027'!$K$2:$K$45,MATCH(ROW()-1,'Registration 2027'!$U$2:$U$53,0)),IF(OR(_xlpm.v=0,_xlpm.v=""),"",_xlpm.v)),"") | I13: =IFERROR(_xlfn.LET(_xlpm.v,INDEX('Registration 2027'!$L$2:$L$45,MATCH(ROW()-1,'Registration 2027'!$U$2:$U$53,0)),IF(OR(_xlpm.v=0,_xlpm.v=""),"",_xlpm.v)),"") | J13: =IFERROR(_xlfn.LET(_xlpm.v,INDEX('Registration 2027'!$N$2:$N$45,MATCH(ROW()-1,'Registration 2027'!$U$2:$U$53,0)),IF(OR(_xlpm.v=0,_xlpm.v=""),"",_xlpm.v)),"") | K13: =IFERROR(INDEX('Registration 2027'!$J$2:$J$45,MATCH(ROW()-1,'Registration 2027'!$U$2:$U$53,0)),"") | M13: =IF(E13="","",IF(COUNTIF($E$2:$E$14,E13)>1,"DUPLICATE","OK")) | O13: Bayview | P13: BAY | Q13: Purple | R13: White
A14: =IF($C14="","",IF($D14="Men","M"&COUNTIF($D$2:$D14,"Men"),"W"&COUNTIF($D$2:$D14,"Women"))) | B14: =IFERROR(INDEX('Registration 2027'!$A$2:$A$45,MATCH(ROW()-1,'Registration 2027'!$U$2:$U$53,0)),"") | C14: =IF($B14="","",IFERROR(_xlfn.XLOOKUP($B14,TeamStyles[Team Name],TeamStyles[Short Name]),"⚠ add to Team Styles")) | D14: =IFERROR(INDEX('Registration 2027'!$B$2:$B$45,MATCH(ROW()-1,'Registration 2027'!$U$2:$U$53,0)),"") | F14: =IF($B14="","",IFERROR(_xlfn.XLOOKUP($B14,TeamStyles[Team Name],TeamStyles[Jersey Home]),"⚠ add to Team Styles")) | G14: =IF($B14="","",IFERROR(_xlfn.XLOOKUP($B14,TeamStyles[Team Name],TeamStyles[Jersey Away]),"⚠ add to Team Styles")) | H14: =IFERROR(_xlfn.LET(_xlpm.v,INDEX('Registration 2027'!$K$2:$K$45,MATCH(ROW()-1,'Registration 2027'!$U$2:$U$53,0)),IF(OR(_xlpm.v=0,_xlpm.v=""),"",_xlpm.v)),"") | I14: =IFERROR(_xlfn.LET(_xlpm.v,INDEX('Registration 2027'!$L$2:$L$45,MATCH(ROW()-1,'Registration 2027'!$U$2:$U$53,0)),IF(OR(_xlpm.v=0,_xlpm.v=""),"",_xlpm.v)),"") | J14: =IFERROR(_xlfn.LET(_xlpm.v,INDEX('Registration 2027'!$N$2:$N$45,MATCH(ROW()-1,'Registration 2027'!$U$2:$U$53,0)),IF(OR(_xlpm.v=0,_xlpm.v=""),"",_xlpm.v)),"") | K14: =IFERROR(INDEX('Registration 2027'!$J$2:$J$45,MATCH(ROW()-1,'Registration 2027'!$U$2:$U$53,0)),"") | M14: =IF(E14="","",IF(COUNTIF($E$2:$E$14,E14)>1,"DUPLICATE","OK")) | O14: Valley Storm HC | P14: VAL | Q14: Teal | R14: White

Sheet Referees Master
A1: REFEREE MASTER
A2: One row per referee: contacts and travel costs. Blue cells = type; Total Cost calculates. Assign referee pairs to games on Games Schedule; driving shifts on Referee Pickup Drop Off.
A3: RefID | B3: Name | C3: Location | D3: Email | E3: Phone | F3: Phone WhatsApp | G3: Type | H3: Flight Cost | I3: Hotel Cost | J3: Per Diem | K3: Car Rental | L3: Total Cost | M3: Payment Method | N3: Pair # | O3: Host-club affiliated? | R3: Referee 1 | S3: Referee 2 | T3: Pair Label (used in schedule) | U3: Host-club pair?
A4: R1 | B4: Selin Ekstrom | C4: Overseas | D4: selin.ekstrom@example.org | E4: 555-0139 | F4: 555-0146 | G4: International | L4: =SUM(H4:K4) | M4: Wire | N4: =ROUNDUP((ROW()-1)/2,0) | O4: No | R4: =B4 | S4: =B5 | T4: =R4&" / "&S4 | U4: =IF(COUNTIFS($N$4:$N$13,ROW()-2,$O$4:$O$13,"Yes")>0,"Yes","No")
A5: R2 | B5: Jasper Holm | C5: Overseas | D5: jasper.holm@example.org | E5: 555-0153 | F5: 555-0160 | G5: International | L5: =SUM(H5:K5) | M5: Wire | N5: =ROUNDUP((ROW()-1)/2,0) | O5: No | R5: =B6 | S5: =B7 | T5: =R5&" / "&S5 | U5: =IF(COUNTIFS($N$4:$N$13,ROW()-2,$O$4:$O$13,"Yes")>0,"Yes","No")
A6: R3 | B6: Camila Duarte | C6: USA | D6: camila.duarte@example.org | E6: 555-0167 | F6: 555-0174 | G6: Domestic | L6: =SUM(H6:K6) | M6: ACH | N6: =ROUNDUP((ROW()-1)/2,0) | O6: No | R6: =B8 | S6: =B9 | T6: =R6&" / "&S6 | U6: =IF(COUNTIFS($N$4:$N$13,ROW()-2,$O$4:$O$13,"Yes")>0,"Yes","No")
A7: R4 | B7: Nico Moretti | C7: USA | D7: nico.moretti@example.org | E7: 555-0181 | F7: 555-0188 | G7: Domestic | L7: =SUM(H7:K7) | M7: ACH | N7: =ROUNDUP((ROW()-1)/2,0) | O7: No | R7: =B10 | S7: =B11 | T7: =R7&" / "&S7 | U7: =IF(COUNTIFS($N$4:$N$13,ROW()-2,$O$4:$O$13,"Yes")>0,"Yes","No")
A8: R5 | B8: Leo Larsen | C8: USA | D8: leo.larsen@example.org | E8: 555-0195 | F8: 555-0102 | G8: Domestic | L8: =SUM(H8:K8) | M8: Check | N8: =ROUNDUP((ROW()-1)/2,0) | O8: No | R8: =B12 | S8: =B13 | T8: =R8&" / "&S8 | U8: =IF(COUNTIFS($N$4:$N$13,ROW()-2,$O$4:$O$13,"Yes")>0,"Yes","No")
A9: R6 | B9: Silas Kaplan | C9: USA | D9: silas.kaplan@example.org | E9: 555-0109 | F9: 555-0116 | G9: Domestic | L9: =SUM(H9:K9) | M9: Check | N9: =ROUNDUP((ROW()-1)/2,0) | O9: No
A10: R7 | B10: Liam Garza | C10: USA | D10: liam.garza@example.org | E10: 555-0123 | F10: 555-0130 | G10: Local | L10: =SUM(H10:K10) | N10: =ROUNDUP((ROW()-1)/2,0) | O10: Yes
A11: R8 | B11: Emeka Dahl | C11: USA | D11: emeka.dahl@example.org | E11: 555-0137 | F11: 555-0144 | G11: Local | L11: =SUM(H11:K11) | N11: =ROUNDUP((ROW()-1)/2,0) | O11: Yes
A12: R9 | B12: Kira Engel | C12: USA | D12: kira.engel@example.org | E12: 555-0151 | F12: 555-0158 | G12: Domestic | L12: =SUM(H12:K12) | N12: =ROUNDUP((ROW()-1)/2,0) | O12: No
A13: R10 | B13: Erik Patel | C13: USA | D13: erik.patel@example.org | E13: 555-0165 | F13: 555-0172 | G13: Domestic | L13: =SUM(H13:K13) | N13: =ROUNDUP((ROW()-1)/2,0) | O13: No
H14: =SUBTOTAL(109,RefereesMaster[Flight Cost]) | I14: =SUBTOTAL(109,RefereesMaster[Hotel Cost]) | J14: =SUBTOTAL(109,RefereesMaster[Per Diem]) | L14: =SUBTOTAL(109,RefereesMaster[Total Cost])

Sheet Medical Staff Master
A1: MEDICAL STAFF MASTER (PHYSIO / ATHLETIC TRAINER)
A2: Type medical staff names & payment handles (blue). Hours pull automatically from the Games Schedule medical staff column; pay = hours × the rate in B3.
A3: Rate ($/hr): | B3: 40
A5: StaffID | B5: Name | C5: Hours Worked | D5: Rate $/Hr | E5: Total Owed | F5: Payment Handle
A6: PT1 | B6: Tomas Toivonen | C6: {=SUMPRODUCT(('Games Schedule'!$AA$5:$AA$31=$B6)*IFERROR('Games Schedule'!$H$5:$H$31-'Games Schedule'!$D$5:$D$31,0))*24} | D6: =$B$3 | E6: =C6*D6 | F6: @tomas-toivonen
A7: PT2 | B7: Kofi Nordin | C7: {=SUMPRODUCT(('Games Schedule'!$AA$5:$AA$31=$B7)*IFERROR('Games Schedule'!$H$5:$H$31-'Games Schedule'!$D$5:$D$31,0))*24} | D7: =$B$3 | E7: =C7*D7 | F7: @kofi-nordin
A8: PT3 | B8: Kira Kim | C8: {=SUMPRODUCT(('Games Schedule'!$AA$5:$AA$31=$B8)*IFERROR('Games Schedule'!$H$5:$H$31-'Games Schedule'!$D$5:$D$31,0))*24} | D8: =$B$3 | E8: =C8*D8 | F8: @kira-kim
A9: PT4 | B9: Astrid Nyberg | C9: {=SUMPRODUCT(('Games Schedule'!$AA$5:$AA$31=$B9)*IFERROR('Games Schedule'!$H$5:$H$31-'Games Schedule'!$D$5:$D$31,0))*24} | D9: =$B$3 | E9: =C9*D9 | F9: @astrid-nyberg
A11: Total | E11: =SUM(E6:E9)

Sheet Products Master
A1: CONCESSION & MERCH PRODUCTS MASTER
A2: One row per item sold at the booth: set Description, Category, COGS & Sale Price (blue). Profit & margin calculate. Feeds Price List Concession and revenue projections. Add items on the first empty table row.
A3: ProductID | B3: Description | C3: Category | D3: COGS | E3: Sale Price | F3: Gross Profit | G3: Gross Margin
A4: F01 | B4: Black coffee, per pod | C4: Beverage | D4: 0.58 | E4: 2.25 | F4: =E4-D4 | G4: =IF(E4=0,0,F4/E4)
